<?xml version="1.0" ?>
<!-- =================================================================================== -->
<!-- |    This document was autogenerated by xacro from car.xacro                      | -->
<!-- |    EDITING THIS FILE BY HAND IS NOT RECOMMENDED                                 | -->
<!-- =================================================================================== -->
<!-- <?xml version="1.0"?>
<robot xmlns:xacro="http://www.ros.org/wiki/xacro" name="Fan"> -->
<!--  -->
<robot name="small_car">
  <material name="green">
    <color rgba="0 0.5 0.2 1"/>
  </material>
  <material name="black">
    <color rgba="0 0 0 1"/>
  </material>
  <material name="white">
    <color rgba="1 1 1 1"/>
  </material>
  <material name="grey">
    <color rgba="0.5843137254901961 0.6392156862745098 0.6509803921568628 1"/>
  </material>
  <link name="base_footprint"/>
<joint name="base_joint" type="fixed">
<parent link="base_footprint"/>
<child link="base_link"/>
<origin rpy="0 0 0" xyz="0 0 0.010"/>
</joint>

  <link name="base_link">
    <visual>
      <geometry>
        <box size="0.35 0.29 0.02"/>
      </geometry>
      <origin rpy="0 0 0" xyz="0 0 0"/>
      <material name="grey"/>
    </visual>
    <collision>
      <geometry>
        <box size="0.35 0.29 0.02"/>
      </geometry>
      <origin rpy="0 0 0" xyz="0 0 0"/>
    </collision>
    <inertial>
      <mass value="0.5"/>
      <!-- box inertia -->
      <inertia ixx="0.005120833333333332" ixy="0.0" ixz="0.0" iyy="0.003520833333333333" iyz="0.0" izz="0.008608333333333332"/>
    </inertial>
  </link>
  <link name="right_front_steering_wheel">
    <inertial>
      <mass value="0.1"/>
      <inertia ixx="1.8958333333333338e-05" ixy="0.0" ixz="0.0" iyy="1.8958333333333338e-05" iyz="0.0" izz="3.125000000000001e-05"/>
    </inertial>
  </link>
  <!-- steering wheel -->
  <joint name="right_front_steering_wheel_joint" type="revolute">
    <axis rpy="0 0 0" xyz="0 0 1"/>
    <parent link="base_link"/>
    <child link="right_front_steering_wheel"/>
    <origin rpy="0 0 0" xyz="0.175 -0.145 -0.035"/>
  </joint>
  <link name="left_front_steering_wheel">
    <inertial>
      <mass value="0.1"/>
      <inertia ixx="1.8958333333333338e-05" ixy="0.0" ixz="0.0" iyy="1.8958333333333338e-05" iyz="0.0" izz="3.125000000000001e-05"/>
    </inertial>
  </link>
  <!-- steering wheel -->
  <joint name="left_front_steering_wheel_joint" type="revolute">
    <axis rpy="0 0 0" xyz="0 0 1"/>
    <parent link="base_link"/>
    <child link="left_front_steering_wheel"/>
    <origin rpy="0 0 0" xyz="0.175 0.145 -0.035"/>
  </joint>
  <link name="right_front_forward_wheel">
    <visual>
      <origin rpy="1.5707963267948966 0 0" xyz="0 0 0"/>
      <geometry>
        <cylinder length="0.02" radius="0.025"/>
      </geometry>
      <material name="black"/>
    </visual>
    <collision>
      <origin rpy="1.5707963267948966 0 0" xyz="0 0 0"/>
      <geometry>
        <cylinder length="0.02" radius="0.025"/>
      </geometry>
    </collision>
    <inertial>
      <mass value="0.1"/>
      <!-- cylinder inertia -->
      <inertia ixx="1.8958333333333338e-05" ixy="0.0" ixz="0.0" iyy="1.8958333333333338e-05" iyz="0.0" izz="3.125000000000001e-05"/>
    </inertial>
  </link>
  <!-- move forward wheel -->
  <joint name="right_front_forward_wheel_joint" type="continuous">
    <axis rpy="0 0 0" xyz="0 1 0"/>
    <parent link="right_front_steering_wheel"/>
    <child link="right_front_forward_wheel"/>
    <origin rpy="0 0 0" xyz="0.0 -0.0 -0.0"/>
  </joint>
  <link name="left_front_forward_wheel">
    <visual>
      <origin rpy="1.5707963267948966 0 0" xyz="0 0 0"/>
      <geometry>
        <cylinder length="0.02" radius="0.025"/>
      </geometry>
      <material name="black"/>
    </visual>
    <collision>
      <origin rpy="1.5707963267948966 0 0" xyz="0 0 0"/>
      <geometry>
        <cylinder length="0.02" radius="0.025"/>
      </geometry>
    </collision>
    <inertial>
      <mass value="0.1"/>
      <!-- cylinder inertia -->
      <inertia ixx="1.8958333333333338e-05" ixy="0.0" ixz="0.0" iyy="1.8958333333333338e-05" iyz="0.0" izz="3.125000000000001e-05"/>
    </inertial>
  </link>
  <!-- move forward wheel -->
  <joint name="left_front_forward_wheel_joint" type="continuous">
    <axis rpy="0 0 0" xyz="0 1 0"/>
    <parent link="left_front_steering_wheel"/>
    <child link="left_front_forward_wheel"/>
    <origin rpy="0 0 0" xyz="0.0 0.0 -0.0"/>
  </joint>
  <link name="right_back_forward_wheel">
    <visual>
      <origin rpy="1.5707963267948966 0 0" xyz="0 0 0"/>
      <geometry>
        <cylinder length="0.02" radius="0.025"/>
      </geometry>
      <material name="black"/>
    </visual>
    <collision>
      <origin rpy="1.5707963267948966 0 0" xyz="0 0 0"/>
      <geometry>
        <cylinder length="0.02" radius="0.025"/>
      </geometry>
    </collision>
    <inertial>
      <mass value="0.1"/>
      <!-- cylinder inertia -->
      <inertia ixx="1.8958333333333338e-05" ixy="0.0" ixz="0.0" iyy="1.8958333333333338e-05" iyz="0.0" izz="3.125000000000001e-05"/>
    </inertial>
  </link>
  <!-- move forward wheel -->
  <joint name="right_back_forward_wheel_joint" type="continuous">
    <axis rpy="0 0 0" xyz="0 1 0"/>
    <parent link="base_link"/>
    <child link="right_back_forward_wheel"/>
    <origin rpy="0 0 0" xyz="-0.175 -0.145 -0.035"/>
  </joint>
  <link name="left_back_forward_wheel">
    <visual>
      <origin rpy="1.5707963267948966 0 0" xyz="0 0 0"/>
      <geometry>
        <cylinder length="0.02" radius="0.025"/>
      </geometry>
      <material name="black"/>
    </visual>
    <collision>
      <origin rpy="1.5707963267948966 0 0" xyz="0 0 0"/>
      <geometry>
        <cylinder length="0.02" radius="0.025"/>
      </geometry>
    </collision>
    <inertial>
      <mass value="0.1"/>
      <!-- cylinder inertia -->
      <inertia ixx="1.8958333333333338e-05" ixy="0.0" ixz="0.0" iyy="1.8958333333333338e-05" iyz="0.0" izz="3.125000000000001e-05"/>
    </inertial>
  </link>
  <!-- move forward wheel -->
  <joint name="left_back_forward_wheel_joint" type="continuous">
    <axis rpy="0 0 0" xyz="0 1 0"/>
    <parent link="base_link"/>
    <child link="left_back_forward_wheel"/>
    <origin rpy="0 0 0" xyz="-0.175 0.145 -0.035"/>
  </joint>
</robot>
