<?xml version="1.0" ?>
<!-- =================================================================================== -->
<!-- |    This document was autogenerated by xacro from car.xacro                      | -->
<!-- |    EDITING THIS FILE BY HAND IS NOT RECOMMENDED                                 | -->
<!-- =================================================================================== -->
<!-- <?xml version="1.0"?>
<robot xmlns:xacro="http://www.ros.org/wiki/xacro" name="Fan"> -->
<!--  -->
<robot name="small_car">
  <material name="green">
    <color rgba="0 0.5 0.2 1"/>
  </material>
  <material name="black">
    <color rgba="0 0 0 1"/>
  </material>
  <material name="white">
    <color rgba="1 1 1 1"/>
  </material>
  <material name="grey">
    <color rgba="0.5843137254901961 0.6392156862745098 0.6509803921568628 1"/>
  </material>
  <!-- car kg -->
  <!-- must -->
  <link name="base_footprint"/>
  <joint name="base_joint" type="fixed">
    <parent link="base_footprint"/>
    <child link="base_link"/>
    <origin rpy="0 0 0" xyz="0 0 0.010"/>
  </joint>
  <!-- car body -->
  <link name="base_link">
    <visual>
      <geometry>
        <box size="0.35 0.27 0.02"/>
      </geometry>
      <origin rpy="0 0 0" xyz="0 0 0"/>
      <material name="grey"/>
    </visual>
    <collision>
      <geometry>
        <box size="0.35 0.27 0.02"/>
      </geometry>
      <origin rpy="0 0 0" xyz="0 0 0"/>
    </collision>
    <inertial>
      <mass value="2"/>
      <!-- box inertia -->
      <inertia ixx="0.02048333333333333" ixy="0.0" ixz="0.0" iyy="0.012216666666666667" iyz="0.0" izz="0.03256666666666666"/>
    </inertial>
  </link>
  <!-- wheel diameter/2 -->
  <link name="right_front_steering_wheel">
    <inertial>
      <mass value="0.1"/>
      <inertia ixx="4.265624999999999e-05" ixy="0.0" ixz="0.0" iyy="4.265624999999999e-05" iyz="0.0" izz="7.03125e-05"/>
    </inertial>
  </link>
  <joint name="right_front_steering_wheel_joint" type="revolute">
    <axis rpy="0 0 0" xyz="0 0 1"/>
    <parent link="base_link"/>
    <child link="right_front_steering_wheel"/>
    <origin rpy="0 0 0" xyz="0.155 -0.1225 -0.0475"/>
  </joint>
  <link name="left_front_steering_wheel">
    <inertial>
      <mass value="0.1"/>
      <inertia ixx="4.265624999999999e-05" ixy="0.0" ixz="0.0" iyy="4.265624999999999e-05" iyz="0.0" izz="7.03125e-05"/>
    </inertial>
  </link>
  <joint name="left_front_steering_wheel_joint" type="revolute">
    <axis rpy="0 0 0" xyz="0 0 1"/>
    <parent link="base_link"/>
    <child link="left_front_steering_wheel"/>
    <origin rpy="0 0 0" xyz="0.155 0.1225 -0.0475"/>
  </joint>
  <link name="right_front_forward_wheel">
    <visual>
      <origin rpy="1.5707963267948966 0 0" xyz="0 0 0"/>
      <geometry>
        <cylinder length="0.03" radius="0.0375"/>
      </geometry>
      <material name="black"/>
    </visual>
    <collision>
      <origin rpy="1.5707963267948966 0 0" xyz="0 0 0"/>
      <geometry>
        <cylinder length="0.03" radius="0.0375"/>
      </geometry>
    </collision>
    <inertial>
      <mass value="0.1"/>
      <!-- cylinder inertia -->
      <inertia ixx="4.265624999999999e-05" ixy="0.0" ixz="0.0" iyy="4.265624999999999e-05" iyz="0.0" izz="7.03125e-05"/>
    </inertial>
  </link>
  <joint name="right_front_forward_wheel_joint" type="continuous">
    <axis rpy="0 0 0" xyz="0 1 0"/>
    <parent link="right_front_steering_wheel"/>
    <child link="right_front_forward_wheel"/>
    <origin rpy="0 0 0" xyz="0.0 -0.0 -0.0"/>
  </joint>
  <link name="left_front_forward_wheel">
    <visual>
      <origin rpy="1.5707963267948966 0 0" xyz="0 0 0"/>
      <geometry>
        <cylinder length="0.03" radius="0.0375"/>
      </geometry>
      <material name="black"/>
    </visual>
    <collision>
      <origin rpy="1.5707963267948966 0 0" xyz="0 0 0"/>
      <geometry>
        <cylinder length="0.03" radius="0.0375"/>
      </geometry>
    </collision>
    <inertial>
      <mass value="0.1"/>
      <!-- cylinder inertia -->
      <inertia ixx="4.265624999999999e-05" ixy="0.0" ixz="0.0" iyy="4.265624999999999e-05" iyz="0.0" izz="7.03125e-05"/>
    </inertial>
  </link>
  <joint name="left_front_forward_wheel_joint" type="continuous">
    <axis rpy="0 0 0" xyz="0 1 0"/>
    <parent link="left_front_steering_wheel"/>
    <child link="left_front_forward_wheel"/>
    <origin rpy="0 0 0" xyz="0.0 0.0 -0.0"/>
  </joint>
  <link name="right_back_forward_wheel">
    <visual>
      <origin rpy="1.5707963267948966 0 0" xyz="0 0 0"/>
      <geometry>
        <cylinder length="0.03" radius="0.0375"/>
      </geometry>
      <material name="black"/>
    </visual>
    <collision>
      <origin rpy="1.5707963267948966 0 0" xyz="0 0 0"/>
      <geometry>
        <cylinder length="0.03" radius="0.0375"/>
      </geometry>
    </collision>
    <inertial>
      <mass value="0.1"/>
      <!-- cylinder inertia -->
      <inertia ixx="4.265624999999999e-05" ixy="0.0" ixz="0.0" iyy="4.265624999999999e-05" iyz="0.0" izz="7.03125e-05"/>
    </inertial>
  </link>
  <joint name="right_back_forward_wheel_joint" type="continuous">
    <axis rpy="0 0 0" xyz="0 1 0"/>
    <parent link="base_link"/>
    <child link="right_back_forward_wheel"/>
    <origin rpy="0 0 0" xyz="-0.155 -0.1325 -0.0475"/>
  </joint>
  <link name="left_back_forward_wheel">
    <visual>
      <origin rpy="1.5707963267948966 0 0" xyz="0 0 0"/>
      <geometry>
        <cylinder length="0.03" radius="0.0375"/>
      </geometry>
      <material name="black"/>
    </visual>
    <collision>
      <origin rpy="1.5707963267948966 0 0" xyz="0 0 0"/>
      <geometry>
        <cylinder length="0.03" radius="0.0375"/>
      </geometry>
    </collision>
    <inertial>
      <mass value="0.1"/>
      <!-- cylinder inertia -->
      <inertia ixx="4.265624999999999e-05" ixy="0.0" ixz="0.0" iyy="4.265624999999999e-05" iyz="0.0" izz="7.03125e-05"/>
    </inertial>
  </link>
  <joint name="left_back_forward_wheel_joint" type="continuous">
    <axis rpy="0 0 0" xyz="0 1 0"/>
    <parent link="base_link"/>
    <child link="left_back_forward_wheel"/>
    <origin rpy="0 0 0" xyz="-0.155 0.1325 -0.0475"/>
  </joint>
  <!-- scan sensor -->
  <link name="base_scan">
    <visual>
      <origin rpy="0 0 0" xyz="0 0 0"/>
      <geometry>
        <cylinder length="0.03" radius="0.02"/>
      </geometry>
      <material name="black"/>
    </visual>
    <collision>
      <origin rpy="0 0 0" xyz="0 0 0"/>
      <geometry>
        <cylinder length="0.03" radius="0.02"/>
      </geometry>
    </collision>
    <inertial>
      <mass value="0.2"/>
      <origin xyz="0 0 0"/>
      <inertia ixx="0.001" ixy="0.0" ixz="0.0" iyy="0.001" iyz="0.0" izz="0.001"/>
    </inertial>
  </link>
  <joint name="scan_joint" type="fixed">
    <parent link="base_link"/>
    <child link="base_scan"/>
    <origin rpy="0 0 0" xyz="0.1 0 0.03"/>
  </joint>
</robot>
